<?xml version="1.0"?>
<sdf version="1.7">
  <model name="TwoLinkRobot">
    <link name="base_link">
      <collision name="base_link_collision">
        <geometry>
          <box>
            <size>0.2 0.2 0.2</size>
          </box>
        </geometry>
      </collision>
    </link>
    <link name="upper_link">
      <pose>0 0.15 0 0 0 0</pose>
      <collision name="upper_link_collision">
        <pose>0 0 -0.5 0 0 0</pose>
        <geometry>
          <cylinder>
            <length>1.1</length>
            <radius>0.05</radius>
          </cylinder>
        </geometry>
      </collision>
    </link>
    <joint name="shoulder" type="revolute">
      <child>upper_link</child>
      <parent>base_link</parent>
      <axis>
        <xyz expressed_in="__model__">0 1 0</xyz>
        <limit>
          <effort>0</effort>
        </limit>
      </axis>
    </joint>
  </model>
</sdf>
